Workbook

Sheet locais
A1: CD_GEOCODMU | B1: NM_MUNICIPIO | C1: NM_UF | D1: CD_CATEGORIA | E1: LAT | F1: LONG | G1: NM_CATEGORIA | H1: NM_LOCALIDADE | I1: NM_MESO | J1: NM_MICRO
A2: 1200013 | B2: ACRELÂNDIA | C2: ACRE | D2: 5 | E2: -100737938924635 | F2: -6.7052317e+15 | G2: CIDADE | H2: ACRELÂNDIA | I2: VALE DO ACRE | J2: RIO BRANCO
A3: 1200054 | B3: ASSIS BRASIL | C3: ACRE | D3: 5 | E3: -1.0942866e+16 | F3: -6.9563459e+15 | G3: CIDADE | H3: ASSIS BRASIL | I3: VALE DO ACRE | J3: BRASILÉIA
A4: 1200104 | B4: BRASILÉIA | C4: ACRE | D4: 5 | E4: -1.1016411e+16 | F4: -6.8747943e+15 | G4: CIDADE | H4: BRASILÉIA | I4: VALE DO ACRE | J4: BRASILÉIA
A5: 1200138 | B5: BUJARI | C5: ACRE | D5: 5 | E5: -9.8200196e+15 | F5: -6.7951859e+15 | G5: CIDADE | H5: BUJARI | I5: VALE DO ACRE | J5: RIO BRANCO
A6: 1200179 | B6: CAPIXABA | C6: ACRE | D6: 5 | E6: -1.0569768e+16 | F6: -6.7673508e+15 | G6: CIDADE | H6: CAPIXABA | I6: VALE DO ACRE | J6: RIO BRANCO
A7: 1200203 | B7: CRUZEIRO DO SUL | C7: ACRE | D7: 5 | E7: -7.63069e+15 | F7: -726725313174358 | G7: CIDADE | H7: CRUZEIRO DO SUL | I7: VALE DO JURUÁ | J7: CRUZEIRO DO SUL
A8: 1200252 | B8: EPITACIOLÂNDIA | C8: ACRE | D8: 5 | E8: -1.102824e+16 | F8: -6.8744868e+15 | G8: CIDADE | H8: EPITACIOLÂNDIA | I8: VALE DO ACRE | J8: BRASILÉIA
A9: 1200302 | B9: FEIJÓ | C9: ACRE | D9: 5 | E9: -8.1602475e+15 | F9: -7.0353984e+15 | G9: CIDADE | H9: FEIJÓ | I9: VALE DO JURUÁ | J9: TARAUACÁ
A10: 1200328 | B10: JORDÃO | C10: ACRE | D10: 5 | E10: -9.1933579e+15 | F10: -7.1950875e+15 | G10: CIDADE | H10: JORDÃO | I10: VALE DO JURUÁ | J10: TARAUACÁ
A11: 1200336 | B11: MÂNCIO LIMA | C11: ACRE | D11: 5 | E11: -7.5932226e+16 | F11: -7.2916501e+15 | G11: CIDADE | H11: MÂNCIO LIMA | I11: VALE DO JURUÁ | J11: CRUZEIRO DO SUL
A12: 1200344 | B12: MANOEL URBANO | C12: ACRE | D12: 5 | E12: -8.8363177e+15 | F12: -692599445775075 | G12: CIDADE | H12: MANOEL URBANO | I12: VALE DO ACRE | J12: SENA MADUREIRA
A13: 1200351 | B13: MARECHAL THAUMATURGO | C13: ACRE | D13: 5 | E13: -8.9535911e+15 | F13: -7.2790266e+15 | G13: CIDADE | H13: MARECHAL THAUMATURGO | I13: VALE DO JURUÁ | J13: CRUZEIRO DO SUL
... A5565: 1722107 | B5565: XAMBIOÁ | C5565: TOCANTINS | D5565: 5 | E5565: -6.411885e+15 | F5565: -4.8531601e+15 | G5565: CIDADE | H5565: XAMBIOÁ | I5565: OCIDENTAL DO TOCANTINS | J5565: ARAGUAÍNA

Sheet BASE TRATADA
A1: MUNICIPIO | B1: UF | C1: POPULACAO | D1: RAZAO SOCIAL | E1: RESPONSAVEL | F1: CONTATO RESPONSAVEL | G1: SEDE DISTRIBUIDOR | H1: CONTATO DISTRIBUIDOR
A2: Acrelândia | B2: AC | C2: 13011 | D2: =IF(IFERROR(VLOOKUP(A1363,'CIDADES ALE'!$A:$D,4,0),0)=0,"Em Branco",VLOOKUP(A1363,'CIDADES ALE'!$A:$D,4,0)) -> Em Branco | E2: =IFERROR(VLOOKUP(D2,'DISTRIBUIDORES ALE'!$A$1:$G$86,2,0),"Em Branco") -> Em Branco | F2: =IFERROR(VLOOKUP(D2,'DISTRIBUIDORES ALE'!$A$1:$G$86,3,0),"Em Branco") -> Em Branco | G2: =IFERROR(VLOOKUP(D2,'DISTRIBUIDORES ALE'!A1:N86,14,0),"Em Branco") -> Em Branco | H2: =IFERROR(VLOOKUP(D2,'DISTRIBUIDORES ALE'!$A$1:$N$86,11,0),"Em Branco") -> Em Branco
A3: Assis Brasil | B3: AC | C3: 6308 | D3: =IF(IFERROR(VLOOKUP(A1364,'CIDADES ALE'!$A:$D,4,0),0)=0,"Em Branco",VLOOKUP(A1364,'CIDADES ALE'!$A:$D,4,0)) -> ELISANGELA CARDOSO SILVA | E3: =IFERROR(VLOOKUP(D3,'DISTRIBUIDORES ALE'!$A$1:$G$86,2,0),"Em Branco") -> Paulo Marques | F3: =IFERROR(VLOOKUP(D3,'DISTRIBUIDORES ALE'!$A$1:$G$86,3,0),"Em Branco") -> 11 9 9744-5591 | G3: =IFERROR(VLOOKUP(D3,'DISTRIBUIDORES ALE'!A2:N87,14,0),"Em Branco") -> AV. SANTOS DUMONT 726 | H3: =IFERROR(VLOOKUP(D3,'DISTRIBUIDORES ALE'!$A$1:$N$86,11,0),"Em Branco") -> 7332815550
A4: Brasiléia | B4: AC | C4: 22261 | D4: =IF(IFERROR(VLOOKUP(A1365,'CIDADES ALE'!$A:$D,4,0),0)=0,"Em Branco",VLOOKUP(A1365,'CIDADES ALE'!$A:$D,4,0)) -> Em Branco | E4: =IFERROR(VLOOKUP(D4,'DISTRIBUIDORES ALE'!$A$1:$G$86,2,0),"Em Branco") -> Em Branco | F4: =IFERROR(VLOOKUP(D4,'DISTRIBUIDORES ALE'!$A$1:$G$86,3,0),"Em Branco") -> Em Branco | G4: =IFERROR(VLOOKUP(D4,'DISTRIBUIDORES ALE'!A3:N88,14,0),"Em Branco") -> Em Branco | H4: =IFERROR(VLOOKUP(D4,'DISTRIBUIDORES ALE'!$A$1:$N$86,11,0),"Em Branco") -> Em Branco
A5: Bujari | B5: AC | C5: 8782 | D5: =IF(IFERROR(VLOOKUP(A1366,'CIDADES ALE'!$A:$D,4,0),0)=0,"Em Branco",VLOOKUP(A1366,'CIDADES ALE'!$A:$D,4,0)) -> Em Branco | E5: =IFERROR(VLOOKUP(D5,'DISTRIBUIDORES ALE'!$A$1:$G$86,2,0),"Em Branco") -> Em Branco | F5: =IFERROR(VLOOKUP(D5,'DISTRIBUIDORES ALE'!$A$1:$G$86,3,0),"Em Branco") -> Em Branco | G5: =IFERROR(VLOOKUP(D5,'DISTRIBUIDORES ALE'!A4:N89,14,0),"Em Branco") -> Em Branco | H5: =IFERROR(VLOOKUP(D5,'DISTRIBUIDORES ALE'!$A$1:$N$86,11,0),"Em Branco") -> Em Branco
A6: Capixaba | B6: AC | C6: 9368 | D6: =IF(IFERROR(VLOOKUP(A1367,'CIDADES ALE'!$A:$D,4,0),0)=0,"Em Branco",VLOOKUP(A1367,'CIDADES ALE'!$A:$D,4,0)) -> Em Branco | E6: =IFERROR(VLOOKUP(D6,'DISTRIBUIDORES ALE'!$A$1:$G$86,2,0),"Em Branco") -> Em Branco | F6: =IFERROR(VLOOKUP(D6,'DISTRIBUIDORES ALE'!$A$1:$G$86,3,0),"Em Branco") -> Em Branco | G6: =IFERROR(VLOOKUP(D6,'DISTRIBUIDORES ALE'!A5:N90,14,0),"Em Branco") -> Em Branco | H6: =IFERROR(VLOOKUP(D6,'DISTRIBUIDORES ALE'!$A$1:$N$86,11,0),"Em Branco") -> Em Branco
A7: Cruzeiro do Sul | B7: AC | C7: 79819 | D7: =IF(IFERROR(VLOOKUP(A1368,'CIDADES ALE'!$A:$D,4,0),0)=0,"Em Branco",VLOOKUP(A1368,'CIDADES ALE'!$A:$D,4,0)) -> ITAVALE DISTRIB. LTDA - EPP | E7: =IFERROR(VLOOKUP(D7,'DISTRIBUIDORES ALE'!$A$1:$G$86,2,0),"Em Branco") -> Paulo Marques | F7: =IFERROR(VLOOKUP(D7,'DISTRIBUIDORES ALE'!$A$1:$G$86,3,0),"Em Branco") -> 11 9 9744-5591 | G7: =IFERROR(VLOOKUP(D7,'DISTRIBUIDORES ALE'!A6:N91,14,0),"Em Branco") -> R TACISIO SAMPAIO, 345 | H7: =IFERROR(VLOOKUP(D7,'DISTRIBUIDORES ALE'!$A$1:$N$86,11,0),"Em Branco") -> 3138257407
A8: Epitaciolândia | B8: AC | C8: 15679 | D8: =IF(IFERROR(VLOOKUP(A1369,'CIDADES ALE'!$A:$D,4,0),0)=0,"Em Branco",VLOOKUP(A1369,'CIDADES ALE'!$A:$D,4,0)) -> ITAVALE DISTRIB. LTDA - EPP | E8: =IFERROR(VLOOKUP(D8,'DISTRIBUIDORES ALE'!$A$1:$G$86,2,0),"Em Branco") -> Paulo Marques | F8: =IFERROR(VLOOKUP(D8,'DISTRIBUIDORES ALE'!$A$1:$G$86,3,0),"Em Branco") -> 11 9 9744-5591 | G8: =IFERROR(VLOOKUP(D8,'DISTRIBUIDORES ALE'!A7:N92,14,0),"Em Branco") -> R TACISIO SAMPAIO, 345 | H8: =IFERROR(VLOOKUP(D8,'DISTRIBUIDORES ALE'!$A$1:$N$86,11,0),"Em Branco") -> 3138257407
A9: Feijó | B9: AC | C9: 32560 | D9: =IF(IFERROR(VLOOKUP(A1370,'CIDADES ALE'!$A:$D,4,0),0)=0,"Em Branco",VLOOKUP(A1370,'CIDADES ALE'!$A:$D,4,0)) -> Em Branco | E9: =IFERROR(VLOOKUP(D9,'DISTRIBUIDORES ALE'!$A$1:$G$86,2,0),"Em Branco") -> Em Branco | F9: =IFERROR(VLOOKUP(D9,'DISTRIBUIDORES ALE'!$A$1:$G$86,3,0),"Em Branco") -> Em Branco | G9: =IFERROR(VLOOKUP(D9,'DISTRIBUIDORES ALE'!A8:N93,14,0),"Em Branco") -> Em Branco | H9: =IFERROR(VLOOKUP(D9,'DISTRIBUIDORES ALE'!$A$1:$N$86,11,0),"Em Branco") -> Em Branco
A10: Jordão | B10: AC | C10: 6898 | D10: =IF(IFERROR(VLOOKUP(A1371,'CIDADES ALE'!$A:$D,4,0),0)=0,"Em Branco",VLOOKUP(A1371,'CIDADES ALE'!$A:$D,4,0)) -> ITAVALE DISTRIB. LTDA - EPP | E10: =IFERROR(VLOOKUP(D10,'DISTRIBUIDORES ALE'!$A$1:$G$86,2,0),"Em Branco") -> Paulo Marques | F10: =IFERROR(VLOOKUP(D10,'DISTRIBUIDORES ALE'!$A$1:$G$86,3,0),"Em Branco") -> 11 9 9744-5591 | G10: =IFERROR(VLOOKUP(D10,'DISTRIBUIDORES ALE'!A9:N94,14,0),"Em Branco") -> R TACISIO SAMPAIO, 345 | H10: =IFERROR(VLOOKUP(D10,'DISTRIBUIDORES ALE'!$A$1:$N$86,11,0),"Em Branco") -> 3138257407
A11: Mâncio Lima | B11: AC | C11: 15890 | D11: =IF(IFERROR(VLOOKUP(A1372,'CIDADES ALE'!$A:$D,4,0),0)=0,"Em Branco",VLOOKUP(A1372,'CIDADES ALE'!$A:$D,4,0)) -> EMBRAPAN - EMPRESA BRASILEIRA DE PANIFICACAO - ME | E11: =IFERROR(VLOOKUP(D11,'DISTRIBUIDORES ALE'!$A$1:$G$86,2,0),"Em Branco") -> Paulo Marques | F11: =IFERROR(VLOOKUP(D11,'DISTRIBUIDORES ALE'!$A$1:$G$86,3,0),"Em Branco") -> 11 9 9744-5591 | G11: =IFERROR(VLOOKUP(D11,'DISTRIBUIDORES ALE'!A10:N95,14,0),"Em Branco") -> AV. SEVERINO BALLESTEROS, 1725 | H11: =IFERROR(VLOOKUP(D11,'DISTRIBUIDORES ALE'!$A$1:$N$86,11,0),"Em Branco") -> 3133571930
A12: Manoel Urbano | B12: AC | C12: 8224 | D12: =IF(IFERROR(VLOOKUP(A1373,'CIDADES ALE'!$A:$D,4,0),0)=0,"Em Branco",VLOOKUP(A1373,'CIDADES ALE'!$A:$D,4,0)) -> EMBRAPAN - EMPRESA BRASILEIRA DE PANIFICACAO - ME | E12: =IFERROR(VLOOKUP(D12,'DISTRIBUIDORES ALE'!$A$1:$G$86,2,0),"Em Branco") -> Paulo Marques | F12: =IFERROR(VLOOKUP(D12,'DISTRIBUIDORES ALE'!$A$1:$G$86,3,0),"Em Branco") -> 11 9 9744-5591 | G12: =IFERROR(VLOOKUP(D12,'DISTRIBUIDORES ALE'!A11:N96,14,0),"Em Branco") -> AV. SEVERINO BALLESTEROS, 1725 | H12: =IFERROR(VLOOKUP(D12,'DISTRIBUIDORES ALE'!$A$1:$N$86,11,0),"Em Branco") -> 3133571930
A13: Marechal Thaumaturgo | B13: AC | C13: 15123 | D13: =IF(IFERROR(VLOOKUP(A1374,'CIDADES ALE'!$A:$D,4,0),0)=0,"Em Branco",VLOOKUP(A1374,'CIDADES ALE'!$A:$D,4,0)) -> Em Branco | E13: =IFERROR(VLOOKUP(D13,'DISTRIBUIDORES ALE'!$A$1:$G$86,2,0),"Em Branco") -> Em Branco | F13: =IFERROR(VLOOKUP(D13,'DISTRIBUIDORES ALE'!$A$1:$G$86,3,0),"Em Branco") -> Em Branco | G13: =IFERROR(VLOOKUP(D13,'DISTRIBUIDORES ALE'!A12:N97,14,0),"Em Branco") -> Em Branco | H13: =IFERROR(VLOOKUP(D13,'DISTRIBUIDORES ALE'!$A$1:$N$86,11,0),"Em Branco") -> Em Branco
... A5566: Xambioá | B5566: TO | C5566: 11458 | D5566: =IF(IFERROR(VLOOKUP(A6927,'CIDADES ALE'!$A:$D,4,0),0)=0,"Em Branco",VLOOKUP(A6927,'CIDADES ALE'!$A:$D,4,0)) -> Em Branco | E5566: =IFERROR(VLOOKUP(D5566,'DISTRIBUIDORES ALE'!$A$1:$G$86,2,0),"Em Branco") -> Em Branco | F5566: =IFERROR(VLOOKUP(D5566,'DISTRIBUIDORES ALE'!$A$1:$G$86,3,0),"Em Branco") -> Em Branco | G5566: =IFERROR(VLOOKUP(D5566,'DISTRIBUIDORES ALE'!A5565:N5650,14,0),"Em Branco") -> Em Branco | H5566: =IFERROR(VLOOKUP(D5566,'DISTRIBUIDORES ALE'!$A$1:$N$86,11,0),"Em Branco") -> Em Branco

Sheet CIDADES ALE
A1: MUNICIPIO | B1: UF | C1: UNIDADE | D1: RAZAO SOCIAL
A2: Abadia dos Dourados | B2: MG | C2: REGIONAL SAO PAULO | D2: RIBERFOODS IMP. E DISTRIB. DE PROD. ALIMENTICIOS LTDA
A3: ABATIA | B3: PR | C3: FILIAL LONDRINA | D3: FILIAL LONDRINA
A4: Abdon Batista | B4: SC | C4: REGIONAL CLIENTES INSTITUCIONAIS | D4: FHILIPPI DISTRIBUIDORA DE ALIMENTOS LTDA
A5: Abelardo Luz | B5: SC | C5: REGIONAL CLIENTES INSTITUCIONAIS | D5: FHILIPPI DISTRIBUIDORA DE ALIMENTOS LTDA
A6: Abre Campo | B6: MG | C6: REGIONAL MG ES RJ | D6: ITAVALE DISTRIB. LTDA - EPP
A7: Açailândia | B7: MA | C7: REGIONAL NORTE-NORDESTE | D7: REVENMOTA IND DE RACOES E COM GEN ALIMENT LTDA
A8: Aceguá | B8: RS | C8: REGIONAL SUL | D8: ÁREA ABERTA - SEM DISTRIBUIDOR
A9: Adamantina | B9: SP | C9: REGIONAL SAO PAULO 2 | D9: CODISPAN COML.DISTR.PRODS.P/PANIF.LTDA.(PEN)
A10: Adrianópolis | B10: PR | C10: REGIONAL SAO PAULO | D10: OUROPAN DISTRIBUIDORA DE PRODUTOS ALIMENTICIOS LTDA
A11: Afrânio | B11: PE | C11: REGIONAL NORTE-NORDESTE | D11: PETROTRIGOS DISTRIBUIDOR DE PRODUTOS DE PAD LTDA
A12: Agronômica | B12: SC | C12: REGIONAL SUL | D12: GELADOS E CONGELADOS DO VALE DISTR LTDA
... A42: Alfredo Chaves | B42: ES | C42: REGIONAL RIO DE JANEIRO | D42: DISVEL DISTRIBUIDORA DE FERMENTO VELOSO LTDA
A43: Alfredo Vasconcelos | B43: MG | C43: REGIONAL MG ES RJ
A44: Almadina | B44: BA | C44: REGIONAL BAHIA | D44: SANTA FE PANIFICADORA IND COM LTDA ME
A45: Almenara | B45: MG | C45: REGIONAL RIO DE JANEIRO | D45: ELISANGELA CARDOSO SILVA
A46: Almirante Tamandaré | B46: PR | C46: FILIAL CURITIBA | D46: FILIAL CURITIBA
A47: Alpestre | B47: RS | C47: REGIONAL CLIENTES INSTITUCIONAIS | D47: FHILIPPI DISTRIBUIDORA DE ALIMENTOS LTDA
A48: Alta Floresta D'Oeste | B48: AP | C48: REGIONAL NORTE | D48: LOJAO DO PADEIRO & CIA LTDA
A49: Altinópolis | B49: SP | C49: REGIONAL SAO PAULO 2 | D49: ADRIPAN PRODUTOS PARA PANIFICACAO LTDA
A50: Alto Alegre | B50: RS | C50: REGIONAL CLIENTES INSTITUCIONAIS | D50: FHILIPPI DISTRIBUIDORA DE ALIMENTOS LTDA
A51: Alto Alegre do Maranhão | B51: MA | C51: REGIONAL NORTE-NORDESTE | D51: REVENMOTA IND DE RACOES E COM GEN ALIMENT LTDA
A52: Alto Bela Vista | B52: SC | C52: REGIONAL CLIENTES INSTITUCIONAIS | D52: FHILIPPI DISTRIBUIDORA DE ALIMENTOS LTDA
A53: Alto Caparaó | B53: MG | C53: REGIONAL MG ES RJ | D53: ITAVALE DISTRIB. LTDA - EPP
A54: Alto Jequitibá | B54: MG | C54: REGIONAL MG ES RJ | D54: ITAVALE DISTRIB. LTDA - EPP
A55: Alto Paraíso | B55: PR | C55: REGIONAL SUL | D55: A.S. JORGE & CIA LTDA
... A57: Alto Piquiri | B57: PR | C57: REGIONAL SUL | D57: A.S. JORGE & CIA LTDA
A58: Alto Rio Doce | B58: MG | C58: REGIONAL MG ES RJ
A59: Alto Rio Novo | B59: ES | C59: REGIONAL RIO DE JANEIRO | D59: COMERCIAL DISKPAN LTDA
A60: Altônia | B60: PR | C60: REGIONAL SUL | D60: A.S. JORGE & CIA LTDA
A61: Alumínio | B61: SP | C61: REGIONAL SAO PAULO | D61: RIBERFOODS IMP. E DISTRIB. DE PROD. ALIMENTICIOS LTDA
A62: Alvarenga | B62: MG | C62: REGIONAL MG ES RJ | D62: ITAVALE DISTRIB. LTDA - EPP
A63: Álvares Machado | B63: SP | C63: REGIONAL SAO PAULO 2 | D63: CODISPAN COML. DISTR. PRODS.P/PANIF. LTDA. (PP)
A64: Alvinópolis | B64: MG | C64: REGIONAL MG ES RJ | D64: EMBRAPAN - EMPRESA BRASILEIRA DE PANIFICACAO - ME
A65: Alvorada | B65: RS | C65: REGIONAL SUL | D65: OESA COMÉRCIO E REPRESENTAÇÕES S.A.
A66: Alvorada de Minas | B66: MG | C66: REGIONAL MG ES RJ | D66: EMBRAPAN - EMPRESA BRASILEIRA DE PANIFICACAO - ME
A67: Alvorada do Norte | B67: DF | C67: REGIONAL CENTRO-OESTE | D67: AMORIX ALIMENTOS LTDA
A68: Alvorada do Norte | B68: GO | C68: REGIONAL CENTRO-OESTE | D68: AMORIX ALIMENTOS LTDA
A69: ALVORADA DO SUL | B69: PR | C69: FILIAL LONDRINA | D69: FILIAL LONDRINA
A70: Amambaí | B70: MS | C70: REGIONAL CENTRO-OESTE
...

Sheet DISTRIBUIDORES ALE
A1: Distribuidor | B1: RESPONSAVEL | C1: TELEFONE | D1: contrato | E1: código | F1: Distribuidor / outros | G1: Nome Fantasia | H1: CNPJ | I1: Insc. Estadual | J1: Contato | K1: Telefone | L1: Celular | M1: Fax | N1: Endereço | O1: Cidade | P1: UF | Q1: CEP | R1: E-mail | S1: ÁREA DE ATUAÇÃO | T1: Uso de Marca FF Contrato | U1: Uso de Marca Contrato Linha Seca | V1: Uso de Marca FF Prática | W1: Uso de Marca Linha Seca Prática
A2: A.S. JORGE & CIA LTDA | B2: Franzen | C2: 51 9 9889-0857 | D2: SIM | E2: 6490 | F2: Distribuidor | G2: A.S. Jorge | H2: 75.516.419/0001-08 | I2: 822.02686-92 | J2: Sr. Milton Simone Jorge e Sra. Anna de Simone Jorge | K2: (44) 3624-1300 / 3624-0301 | L2: (44) 9924-9533 | M2: (44) 3624-0301 | N2: Av. Londrina, 3646 | O2: Umuarama | P2: PR | Q2: 87502250 | R2: miltonsimone@creapr.org.br; asjorge@creapr.org.br; | S2: PARANÁ: Alto Piquiri, Alto Paraíso, Altônia, Araruna, Assis Chateaubriand, Boa Esperança, Brasilândia do Sul, Cafezal do Sul, Cianorte, Cidade Gaúcha, Cruzeiro do Oeste, Douradina, Esperança Nova, Farol, Formosa do Oeste, Francisco Alves, Goioerê, Guairá, Guaporema, Icaraíma, Iracema do Oeste, Iporã, Ivaté, Janiópolis, Jesuítas, Loanda, Mamborê, Maria Helena, Mariluz, Maripá, Mirador, Moreira Sales, Nova Olímpia, Palotina, Perobal, Pérola, Planaltina do Paraná, Porto Rico, Quarto Centenário, Querência do Norte, Rancho Alegre D'Oeste, Santa Cruz do Monte Castelo, Santa Isabel do Ivaí, Santa Mônica, São Jorge do Patrocínio, São Pedro do Paraná, Tapejara, Tapira, Terra Roxa, Tuneiras do Oeste, Umuarama, Xambrê. | T2: 0.22 | U2: - | V2: 0.15 | W2: 0.2
A3: ADRIPAN PRODUTOS PARA PANIFICACAO LTDA | B3: Celso Chaves | C3: 14 9 8808-5285 | D3: SIM | E3: 103318 | F3: Distribuidor | G3: Adripan | H3: 09.502.990/0001-30 | I3: 582771507119. | J3: Sra. Adriana Helena Andreucci e Sr. José Marcos Carreira | K3: (16) 3236-3049 | L3: (16) 9167-5533 | M3: (16) 3236-3050 | N3: Rua Barretos, 115 – Vila Elisa, | O3: Ribeirão Preto | P3: SP | Q3: 14075-000 | R3: adripanrp@hotmail.com | S3: SÃO PAULO: Altinópolis, Américo Brasiliense, Analândia, Aramina, Araraquara, Barrinha, Batatais, Brodowski, Buritizal, Cajurú, Cássia dos Coqueiros, Cravinhos, Cristais Paulista, Descalvado, Dobrada, Dourado, Dumont, Franca, Guará, Guariba, Guatapará, Ibaté, Igarapava, Ipuã, Itirapina, Itirapuã, Ituverava, Jaborandi, Jaboticabal, Jardinópolis, Jeriquara, Leme, Luís Antônio, Matão, Miguelópolis, Monte Alto, Morro Agudo, Motuca, Nuporanga, Orlândia, Patrocínio Paulista, Pedregulho, Pirassununga, Pitangueiras, Pontal, Porto Ferreira, Pradópolis, Restinga, Ribeirão Bonito, Ribeirão Corrente, Ribeirão Preto, Rifaina, Rincão, Sales Oliveira, Santa Cruz da Conceição, Santa Cruz da Esperança, Santa Cruz das Palmeiras, Santa Ernestina, Santa Lúcia, Santa Rita do Passa Quatro, Santa Rosa do Viterbo, Santo Antônio da Alegria, São Carlos, São Joaquim da Barra, São José da Bela Vista, São Simão, Serra Azul, Serrana, Sertãozinho, Tambaú, Taquaritinga, Terra Roxa, Trabiju, Viradouro. | T3: 0.15 | U3: 0.2 | V3: - | W3: -
A4: AL MOTTA SANTOS | B4: Renato Evangelista | C4: 71 9 8817-1056 | D4: NÃO | E4: 603606 | F4: Distribuidor | G4: Trigo e Cia | H4: 09.086.607/0001-00 | I4: 75203376 | J4: Sr. Nevson Sena | K4: ( 75) 3221-2073 | L4: (75) 9138-6945 / 8864-2061 | M4: (75) 3221-2073 | N4: Rua C , 26 Cj. Feira IV - Caminho 11 | O4: Feira de Santana | P4: BA | Q4: 44008-090 | R4: nevsonsena@gmail.com; mottasena@gmail.com | S4: BAHIA: Feira de Santana e Região | T4: - | U4: - | V4: - | W4: -
A5: AMORIX ALIMENTOS LTDA | B5: Celso Chaves | C5: 14 9 8808-5285 | D5: SIM | E5: 111998 | F5: Distribuidor | G5: AMORIX | H5: 26.452.694/0001-91 | I5: 106907689 | J5: Sr. Rodolfo Amorim | K5: (62) 3202-3200 | L5: (62) 9686 8797 | M5: (62) 32834878 | N5: Via Acesso 04, SN Quadra E lote 10, Chácara Marivênia | O5: Aparecida de Goiânia | P5: GO | Q5: 74.923-130 | R5: rodolfosamorim@gmail.com; compras2@amorix.com.br;contasapagar@amorix.com.br;cristiano@amorix.com.br;fiscal@amorix.com.br; | S5: GOIÁS: Alvorada do Norte ,Anápolis,Aparecida de Goiânia,Araguapaz,Aurilândia,Barro Alto,Bela Vista de Goiás,Britânia,Caldas Novas,Campinorte,Campo Limpo de Goiás,Carmo do Rio Verde,Ceres,Cezarina,Cocalzinho de Goiás,Corumbá de Goiás,Crixás,Estrela do Norte,Fazenda Nova,Firminópolis,Goianésia,Goiânia,Goianira,Guapó,Heitoraí,Hidrolândia,Inhumas,Iporá,Israelândia,Itaberaí,Itapaci,Itapirapuã,Itapuranga,Itauçú,Jaraguá,Jussara,Mara Rosa,Mozarlândia,Nazário,Nerópolis,Niquelândia,Nova Glória,Palmeiras de Goiás,Paraúna,Piracanjuba,Pires do Rio,Porangatu,Rialma,Rianápolis,Rubiataba,Santa Fé de Goiás,Santa Teresa de Goiás,Santa Terezinha de Goiás,São Luís de Montes Belos,São Miguel do Araguaia,Silvânia,Taquaral de Goiás,Trindade,Turvânia,Uruaçú,Uruana(TOCANTINS)Araguaína,Barrolândia,Cristalândia,Fátima,Guaraí,Gurupi,Miranorte,Natividade ,Porto Nacional,Tocantinópolis. DISTRITO FEDERAL: Águas Claras, Brasília, Brazilândia, Candangolândia, Ceilândia, Cruzeiro, Fercal, Gama, GuaráI, GuaráII, Itapoã, Núcleo Bandeirante, Octogonal, Park way, Recanto das Emas, Santa Maria, São Sebastião, Sobradinho, Sudoeste, Taguatinga, Varjão, Vicente Pires. (GOIÁS) - Águas Lindas, Alexânia, Alvorada do Norte, Cidade Ocidental, Cristalina, Formosa, Girassol, Iaciara, Luziânia, Monte Alegre de Goiás, Padre Bernardo, Paranoá, Planaltina, Palnaltina de Goiás, Posse, Santo Antônio do Descoberto, São Domingos, Samambaia, Simolândia, Valparaíso de Goiás (MINAS GERAIS) - João Pinheiro, Paracatú.(TOCANTINS) - Arraias, Dianópolis. | T5: 0.15 | U5: 0.15 | V5: - | W5: -
A6: ÁREA ABERTA - SEM DISTRIBUIDOR | B6: Franzen | C6: 51 9 9889-0857 | S6: SANTA CATARINA: Águas Mornas, Alberto Leal, Angelina, Antonio Carlos, Biguaçú, Botuverá, Canelinha, Florianópolis, Governador Celso Ramos, Guabiruba, Major Gercino, Nova Trento, Palhoça, Rancho Queimado, Santo Amaro da Imperatriz, São João Batista, São José, São Pedro de Alcântara. | T6: - | U6: - | V6: - | W6: -
A7: ÁREA ABERTA - SEM DISTRIBUIDOR | B7: Franzen | C7: 51 9 9889-0857 | S7: RIO GRANDE DO SUL: Encruzilhada do Sul, Dom Feliciano, Chuvisca, Amaral Ferrador, Santana da Boa Vista, Lavras do Sul, Dom Pedrito, Bagé, Hulha Negra, Candiota, Pinheiro Machado, Pedras Altas, Aceguá, Barra do Ribeiro, Mariana Pimentel, Barão do Triunfo, Sertão Santana, Cerro Grande do Sul, Sentinela do Sul, Tapes, Camaquã, Arambaré, Cristal, São Lourenço do Sul, Canguçú, Piratini, Arroio Grande, Turuçu, Morro Redondo, Pelotas, Capão Leão, Cerrito, Pedro Osório, Herval, Jaguarão, Santa Vitoria do Palmar, Chuí. | T7: - | U7: - | V7: - | W7: -
A8: ATACADAO JLJ DISTRIBUIDORA DE ALIMENTOS LTDA | B8: Cláudio Cardoso | C8: 83 8 3822-0300 | D8: NÃO | E8: 117100 | F8: Distribuidor | G8: ATACADAO JLJ DISTRIBUIDORA DE ALIMENTOS LTDA | H8: 45301905000130 | I8: 102280398 | J8: JORGE NEY ALVES DA CRUZ | K8: 8132242118 | N8: RUA SATURNINO MEIRELES, 69 | O8: RECIFE | P8: PE | Q8: 51190090 | R8: lucas.lorena@hotmail.com; | S8: PE: RECIFE | T8: - | U8: - | V8: - | W8: -
A9: AZEVEDO RIBEIRO & CIA LTDA | B9: Franzen | C9: 51 9 9889-0857 | D9: SIM | E9: 1200005 | F9: Distribuidor | G9: Azevedo Ribeiro | H9: 89.842.726/0001-57 | I9: 029/0116341 | J9: Sr. Altair de Azevedo Ribeiro / Sra. Renata Maria Ribeiro | K9: (54) 3221-8544 / 3221-8156 | L9: (54) 9972-8602 | M9: (54) 3221-8544 | N9: R. Hercules Galló, 1320 | O9: Caxias do Sul | P9: RS | Q9: 95020-330 | R9: azevedo_ribeiro@hotmail.com | S9: RIO GRANDE DO SUL:Antônio Prado, Arroio do Sal, Balneário Pinhal, Bom Jesus, Cambará do Sul, Campestre da Serra, Capão da Canoa, Capivari do Sul, Caraá, Caxias do Sul, Cidreira, Dom Pedro de Alcântara, Farroupilha, Flores da Cunha, Imbé, Ipê, Itati, Jaquirana, Mampituba, Maquiné, Monte Alegre dos Campos, Morrinhos do Sul, Mostardas, Nova Pádua, Nova Roma do Sul, Osório, Palmares do Sul, Santo Antonio da Patrulha, São José dos Ausentes, São Marcos, Tavares, Terra de Areia, Torres, Tramandaí, Três Cachoeiras, Três Forquilhinhas, Vacaria, Xangrilá. | T9: 0.15 | U9: 0.2 | V9: 15% e 20% | W9: 15% e 20%
A10: BASTOS BARBOSA DIST.DE ALIM.LTDA | B10: Paulo Marques | C10: 11 9 9744-5591 | D10: NÃO | E10: 105841 | F10: Distribuidor | G10: BASTOS BARBOSA DIST.DE ALIM.LTDA | H10: 11216374000165 | I10: 78878282 | J10: Mauro | K10: (22) 27350771/27225543 | N10: R ALONSO PER.GOMES, 40 | O10: CAMPOS DOS GOYTACAZES | P10: RJ | Q10: 28015130 | R10: cecaldistribuidora@bol.com.br; | S10: Estado do Rio de Janeiro: Bom Jesus do Itabapoana, Cambuci, Campos de Goitacazes, Carapebus, Cardoso Moreira, Italva, Conceição de Macabu, Itaperuna, Laje do Muriaé, Miracema, Natividade, Porciúncula, Quissamã, São Fidelis, São Francisco de Itabapoana, São João da Barra, São José de Ubá, Varre-Sai, | T10: - | U10: - | V10: - | W10: -
A11: BISCOITOS E BOLACHAS SKIN LTDA - ME | B11: Cláudio Cardoso | C11: 83 8 3822-0300 | D11: NÃO | E11: 117340 | F11: Distribuidor | G11: BISCOITOS E BOLACHAS SKIN LTDA - ME | H11: 23726745000138 | I11: 65163940 | J11: CLEITON DE LIMA SILVA | K11: 8737961021 | N11: SIT BARROCAS, 1000 | O11: CAETÉS | P11: PE | Q11: 55360000 | R11: anajuliafonseca@itaiquara.com.br;jarbasavelino@hotmail.com; | S11: PE: CAETÉS | T11: - | U11: - | V11: - | W11: -
A12: CARLOS ROBERTO MASCARELO JUNIOR - ME | B12: Wanessa Fabrina | C12: 11 9 8991-3766 | D12: NÃO | E12: 117218 | F12: Distribuidor | G12: Mascarelo | H12: 28.454.971/0001-20 | I12: 530057032116 | J12: Sr. Carlos Roberto Mascarelo | K12: (13) 3651-1572 | N12: Rua Áurea Soares Caldas Bueno, nº 70 | O12: Espírito Santo do Pinhal | P12: SP | Q12: 13.990-000 | R12: mascarelo.cia@gmail.com | S12: SÃO PAULO: Águas da Prata, Espírito Santo do Pinhal, Santo Antônio do Jardim, São João da Boa Vista, São Sebastião da Grama, Vargem Grande do Sul. (No Estado de MINAS GERAIS) – Andradas, Bandeira do Sul, Botelhos, Cabo Verde, Caldas, Campestre, Ibitiúra de Minas, Poços de Caldas, Santa Rita de Caldas.
A13: CASSIO ANDRE SCHMITT EIRELI ME | B13: Franzen | C13: 51 9 9889-0857 | D13: NÃO | E13: 117076 | F13: Cliente | G13: CASSIO ANDRE SCHMITT EIRELI ME | H13: 24203351000168 | I13: 1170099871 | J13: Sr. Cassio André Schimitt | K13: 1936579000 | L13: (55) 9975-3144 | N13: RUA GEN MARQUES, 1264 | O13: São Borja | P13: RS | Q13: 97670000 | R13: kitute@kitute.com.br; | S13: RIO GRANDE DO SUL: São Borja. | T13: - | U13: - | V13: - | W13: -
A14: CCN – COMERCIAL CENTRO NORTE ALIMENTOS LTDA | B14: Paulo Marques | C14: 11 9 9744-5591 | D14: CONCESSÃO | E14: 107648 | F14: Distribuidor | G14: CCN | H14: 08.638.790/0001-47 | I14: 78.258.02-0 | J14: André Kauark Chianca | K14: (22) 2519-9900 | N14: Avenida Nossa Senhora do Amparo, S/N - Prado | O14: Nova Friburgo | P14: RJ | Q14: 28.635-010, | R14: rafael.almeida@ccndistribuidora.com.br | S14: ”Rio de Janeiro - Baixada Fluminense: Duque de Caxias, São João de Meriti, Nova Iguaçu, Japeri, Paracambi, Belford Roxo, Seropédica, Queimados, Itaguaí, Nilópolis, Magé | T14: - | U14: - | V14: - | W14: -
A15: CITI PAN PRODUTOS ALIMENTICIOS EIRELI | B15: Paulo Marques | C15: 11 9 9744-5591 | D15: NÃO | E15: 815727 | F15: Distribuidor | G15: CITI PAN PRODUTOS ALIMENTICIOS EIRELI | H15: 26743123000106 | I15: 87288765 | J15: Dieine | K15: 2433232164 | M15: 24998428582 | N15: AV HOMERO LEITE, 206 | O15: BARRA MANSA | P15: RJ | Q15: 27313190 | R15: contasapagar79@yahoo.com.br;d.rodriguesbm@yahoo.com.br; | S15: RIO DE JANEIRO: Angra dos Reis, Barra do Piraí, Barra Mansa, Itatiaia, Mangaratiba, Parati, Pinheiral, Piraí, Porto Real, Quatis, Resende, Rio Claro, Rio das Flores, Valença, Volta Redonda. | T15: - | U15: - | V15: - | W15: -
A16: CLÁUDIO GONÇALVES PEREZ | B16: Franzen | C16: 51 9 9889-0857 | D16: NÃO | E16: 1205512 | F16: Distribuidor | G16: Cláudio | H16: 661.697.120-15 | I16: N/C | J16: Sr. Cláudio Gonçalves | L16: (53) 99988-5060 | M16: _ | N16: Rua Caramuru, 358 - Cidade Nova | O16: Rio Grande | P16: RS | Q16: 96211-500 | R16: claudioperes591@gmail.com | S16: Rio Grande do Sul: Rio Grande, Cassino, Santa Vitória do Palmar | T16: N/C | U16: N/C | V16: N/C | W16: N/C
A17: CODISPAN COML. DISTR. PRODS.P/PANIF. LTDA. (PP) | B17: Celso Chaves | C17: 14 9 8808-5285 | D17: SIM | E17: 99124 | F17: Distribuidor | G17: Codispan Presidente Prudente | H17: 58. 072 935/0005-97 | I17: 562 256 848-110 | J17: Sr. Jovino Fonseca Neto | K17: (18) 3908-4008 | L17: (18) 9786-2590 | M17: (18) 3908-4008 | N17: Av Joaquim Constantino, 1300 | O17: Presidente Prudente | P17: SP | Q17: 19050-220 | R17: codispan.pp@terra.com.br | S17: FILIAL PRESIDENTE PRUDENTE: Adamantina,Álvares Machado,Anhumas,Assis,Cândido Mota,Chavantes,Cruzália,Dracena,Flora Rica,FlóridaPaulista,Florínia,Ibirarema,Irapuru,Junqueirópolis,Lucélia,Maracaia ( Maracaí),Martinópolis,Mirante de Paranapanema,Osvaldo Cruz,Ourinhos,Ouro Verde,Pacaembú,Palmital,Panorama,Parapuã,Pedrinhas Paulista,Pirapozinho,Presidente Bernardes,Presidente Epitácio,Presidente Prudente,Presidente Venceslau,Regente Feijó,Rosana,Santo Anastácio,Tarumã,Teodoro Sampaio ,Tupi Paulista (MATO GROSSO DO SUL) - Bataguassu (PP), | T17: 0.1353 | U17: 0.1353 | V17: - | W17: -
A18: CODISPAN COML.DISTR.PRODS.P/PANIF.LTDA.(PEN) | B18: Celso Chaves | C18: 14 9 8808-5285 | D18: SIM | E18: 6466 | F18: Distribuidor | G18: Codispan Matriz | H18: 58.072.935/0001-63 | I18: 562256848110. | J18: Sr. Jovino Fonseca Neto | K18: (18) 3652-0577 | L18: (18) 9781-7470 | M18: (18) 3652-0952 | N18: Av.Leandro R. de Medeiros, 714 | O18: Penápolis | P18: SP | Q18: 16300000 | R18: codispan@terra.com.br | S18: MATRIZ PENÁPOLIS: Andradina,Araçatuba,Avanhandava,Balbinos,Bastos,Bento de Abreu,Bilac,Birigui,Braúna,Cafelândia,Castilho,Clementina,Gabriel Monteiro,Gália,Garça,Getulina,Glicério,Guaiçara,Guaimbê,Guaraçaí,Guarantã,Guararapes,Herculândia,Iacri,Ilha Solteira,Itapura,Lavínia,Lins,Marília,Mirandópolis,Murutinga do Sul,Oriente,Paraguaçú Paulista,Penápolis,Pereira Barreto,Pirajuí,Pompéia,Presidente Alves,Promissão,Quatá,Quintana,Rancharia,Rinópolis,Santópolis do Aguapeí,Tupã,Valparaíso,Vera Cruz (MATO GROSSO DO SUL) - (Três Lagoas(P.) | T18: 0.1353 | U18: 0.1353 | V18: - | W18: -
A19: CODISPAN COML.DISTR.PRODS.PANIF.LTDA.(BAURU) | B19: Celso Chaves | C19: 14 9 8808-5285 | D19: SIM | E19: 6467 | F19: Distribuidor | G19: Codispan Bauru | H19: 58 072 935 0003/25 | I19: 209 203 564-117 | J19: Sr. Jovino Fonseca Neto | K19: (14) 3227-1132 | M19: (14) 3224-3549 | N19: R. Floriano Peixoto, 231 | O19: Bauru | P19: SP | Q19: 17015-090 | R19: codispanbauru@terra.com.br | S19: FILIAL BAURU: Águas de Santa Bárbara,Agudos,Arandu,Areiópolis ,Avaré,Barra Bonita,Bauru,Bernardino de Campos,Botucatu,Brotas,Cabrália Paulista,Cerqueira César,Dois Córregos,Duartina,Fartura,Iaras,Igaraçú do Tietê,Ipaussu,Itaí,Itapuí,Itatinga,Jaú,Lençóis Paulista,Macatuba,Mineiros do Tietê,Pederneiras,Piraju,Piratininga,Pratânia,Salto Grande,Santa Cruz do Rio Pardo,São Manuel,Sarutaiá,Taguaí,Taquarituba,Torrinha | T19: 0.1353 | U19: 0.1353 | V19: - | W19: -
A20: COM REPRES MACRIZA LTDA | B20: Franzen | C20: 51 9 9889-0857 | D20: SIM | E20: 1200000 | F20: Distribuidor | G20: Macriza | H20: 90.007.667/0001-09 | I20: 430028164 | J20: Sr. Gustavo Zanini e Sra. Daiane Zanini | K20: (51) 3473-1115 | L20: (51) 9989-6815 | M20: (51) 3473-1115 | N20: R. Taquari, 70 | O20: Esteio | P20: RS | Q20: 93285550 | R20: macriza84@yahoo.com.br | S20: RIO GRANDE DO SUL: Campo Bom, Canela, Dois Irmãos, Estância Velha, Gramado, Igrejinha, Ivoti, Novo Hamburgo, Nova Hartz, Parobé, Riozinho, Rolante, Santa Maria do Herval, São Francisco de Paula, São Leopoldo, Sapiranga, Sapucaia do Sul, Taquara, Três Coroas. RIO GRANDE DO SUL: Arroio dos Ratos, Butiá, Brochier, Charqueadas, Esteio, General Câmara, Harmonia, Minas do Leão, Montenegro, Paverama, Portão, São Jerônimo, São Sebastião do Caí, Tabal, Taquari, Triunfo, Canoas, Gravataí e Cachoeirinha. | T20: 0.15 | U20: 0.2 | V20: 15% e 20% | W20: 15% e 20%
A21: COMERCIAL BERNARDI & BERNARDI LTDA | B21: Paulo Marques | C21: 11 9 9744-5591 | D21: CONCESSÃO | E21: 108223 | F21: Distribuidor | G21: COMERCIAL BERNARDI & BERNARDI LTDA | H21: 9144287000106 | I21: 10479560072 | J21: Rodrigo | K21: 3532251111 | M21: 3599213177 | N21: RUA DOM INOCENCIO, 1051 | O21: CARMO DA CACHOEIRA | P21: MG | Q21: 37225000 | R21: disppan@disppan.com.br;fatimacbbernardi@gmail.com;rodrigocbernardi@hotmail.com | S21: MINAS GERAIS: Aiuruoca, Alagoa, Albertina, Arantina, Baependí, Bocâina de Minas, Bom Repouso, Bom Sucesso, Borda da Mata, Brasópolis, Bueno Brandão, Cachoeira de Minas, Camanducaia, Cambuí, Cambuquira, Campanha, Campo Belo, Cana Verde Candeias, Carmo da Cachoeira, Carmo de Minas, Carrancas, Caxambú, Conceição dos Ouros, Cogonhal, Conceição das Pedras, Conceição do Rio Verde, Consolação, Coreaçú, Córrego Bom Jesus, Cristina, Cruzílha, Delfím Moreira, Dom Viçoso, Estiva, Extrema, Heliodora, Ibituruna, Ijaci, Inconfidentes, Ingaí, Ipuiuna, Itajubá, Itamonte, Itanhandú, Itapeva, Itumirim, Itutinga, Jacutinga, Jesuânia, Lambarí, Lavras, Luminárias, Maria da Fé, Marmelópolis, Monsenhor Paulo, Natércia, Olimpio Noronha, Ouro Fino, Paraisópolis, Passa Quatro, Pedralva, Perdões, Piranguçú, Piranguinho, Pouso Alegre, Pouso Alto, Ribeirão Vermelho, São S. do Rio Verde, Santa Rita do Sapucaí, Santana do Jacaré, Santo Antonio do Amparo, São José do Alegre, São Lourenço, São Gonçalo do Sapucaí, São S. da Bela Vista, São Bento do Abade, São Thiago, São Thomé das Letras, Sapucáia Mirim, Senador Amaral, Senador José Bento, Serranos, Soledade de Minas, Tocos do Mogí, Toledo, Três Corações, Venceslau Braz, Virgínia | T21: 0.15 | U21: 0.2 | V21: - | W21: -
A22: COMERCIAL DE ALIMENTOS PÃO QUENTE LTDA | B22: Franzen | C22: 51 9 9889-0857 | D22: NÃO | E22: 117226 | F22: Distribuidor | G22: Atacado Pão Quente | H22: 79.395.661/0001-13 | I22: 251355128 | J22: Sr. Vanio e Sr. Kinho | K22: (48) 3433-4735 | L22: (48) 98844-4626 | M22: (48) 3433-4735 | N22: Rua Duarte da Costa 829 | O22: Criciúma | P22: SC | Q22: 88803-150 | R22: comercialpaoquente@hotmail.com | S22: SANTA CATARINA: Anitápolis, São Bonnifácio, Paulo Lopes, Santa Rosa de Lima, Garopaba, Rio Fortuna, São Martinho, Grão Pará, Braço do Norte, Armazém, Imbituba, Orleans, São Ludgero, Gravatal, Imaruí, Lauro Muller, Treviso, Urussanga, Pedras Grandes, Tubarão, Capivari de Baixo, Laguna, Siderópolis, Cocal do Sul, Treze de Maio, Nova Veneza, Criciúma, Morro da Fumaça, Sangão, Jaguaruna, Timbé do Sul, Morro Grande, Içara, Forquilinha, Meleiro, Maracajá, Turvo, Araranguá, Jacinto Machado, Ermo, Balneário Arroio Silva, Sombrio, Santa Rosa do Sul, Praia Grande, São João do Sul, Balneário Gaivota, Passo de Torres. | T22: N/C | U22: N/C | V22: N/C | W22: N/C
A23: COMERCIAL DISKPAN LTDA | B23: Paulo Marques | C23: 11 9 9744-5591 | D23: NÃO | E23: 107438 | F23: Distribuidor | G23: COMERCIAL DISKPAN LTDA | H23: 2691482000107 | I23: 81967551 | J23: Vilma/Ademir | K23: 2732468500 | N23: AVENIDA FERNANDO ANTONIO, 1911 | O23: CARIACICA | P23: ES | Q23: 29140669 | R23: compras@diskpan.com.br;contasapagar@diskpan.com.br; | S23: ESPÍRITO SANTO - Água Doce do Norte, Águia Branca, Alto Rio Novo, Aracruz, Baixo Guandu, Barra de São Francisco, Boa Esperança, Cariacica, Colatina, Conceição da Barra, Domingos Martins, Ecoporanga, Fundão, Governador Lindenberg, Ibiraçu, Itaguaçu, Itarana, Jaguaré, João Neiva, Linhares, Mantenópolis, Marechal Floriano, Marilandia, Montanha, Mucurici, Nova Venécia, Pancas, Pedro Canário, Pinheiros, Ponto Belo, Rio Bananal, Santa Leopoldina, Santa Maria do Jetibá, Santa Teresa, São Domingos do Norte, São Gabriel da Palha, São Mateus, São Roque do Canaã, Serra, Sooretama, Viana, Vila Pavão, Vila Valério, Vila Velha e Vitória. | T23: - | U23: - | V23: - | W23: -
A24: COML. FERMENTOS MAZIFRAN LTDA | B24: Franzen | C24: 51 9 9889-0857 | D24: SIM | E24: 4222 | F24: Distribuidor | G24: Mazifran | H24: 79.438.347/0001-70 | I24: 301.00277-71 | J24: Sr. Francisco José Schreiner e Sra. Zilda Filomena Kretzer Schreiner | K24: (42) 3522-2230 | L24: (42) 8805-4172 | M24: (42) 3522-2230 | N24: R. Marechal Deodoro, 1400 | O24: União da Vitoria | P24: PR | Q24: 84600-000 | R24: mazifran@uvaol.com.br | S24: PARANÁ: Agudos do Sul, Antônio Olinto, Bituruna, Campo do Tenente, Cruz Machado, General Carneiro, Paula Freitas, Paulo Frontim, Piên, Porto Vitória, Quitandinha, Rio Negro, São João do Triunfo, São Mateus do Sul, Tijucas do Sul, União da Vitória, e no Estado de SANTA CATARINA - Bela Vista do Toldo, Campo Alegre, Canoínhas, Irineópolis, Itaiópolis, Mafra, Major Vieira, Monte Castelo, Papanduva, Porto União, Rio Negrinho, São Bento do Sul, Três Barras. | T24: 0.15 | U24: 0.2 | V24: 15% e 50% | W24: 15% e 50%
A25: DISTRIBUIDORA IMP E EXP DE FERMENTO CAMPINAS LTDA | B25: Wanessa Fabrina | C25: 11 9 8991-3766 | D25: SIM | E25: 103296 | F25: Distribuidor | G25: Gapan | H25: 09.419.860/0001-39 | I25: 244775560119. | J25: Sr. Lauro Gabriel Júnior | K25: (19) 3208-1334 | L25: (19) 97806-8135 | M25: (19) 3208-1492 | N25: R. Domingos Cazotti, 155 | O25: Campinas | P25: SP | Q25: 13080-000 | R25: junior@gapan.com.br | S25: SÃO PAULO: Águas de Lindóia, Águas de São Pedro, Americana, Amparo, Araras, Artur Nogueira, Atibaia, Bom Jesus dos Perdões, Bragança Paulista, Cabreúva, Campinas, Campo Limpo Paulista, Charqueada, Conchal, Cordeirópolis, Cosmópolis, Engenheiro Coelho, Estiva Gerbi, Holambra, Hortolândia, Igaratá, Ipeúna, Iracemápolis, Itapira, Itatiba, Itupeva, Jaguariúna, Jarinu, Joanópolis, Jundiaí, Limeira, Lindóia, Louveira, Mogi-Guaçu, Mogi-Mirim, Mombuca, Monte Alegre do Sul, Morungaba, Nazaré Paulista, Nova Odessa, Paulínia, Pedra Bela, Pedreira, Pinhalzinho, Piracaia, Piracicaba, Pirapora do Bom Jesus, Rio Claro, Rio das Pedras, Saltinho, Santa Bárbara D´Oeste, Santa Gertrudes, Santa Maria da Serra, Santo Antônio da Posse, São Pedro, Serra Negra, Socorro, Sumaré, Tuiuti, Valinhos, Vargem, Várzea Paulista, Vinhedo (ESTADO DE MINAS GERAIS) – Extrema, Monte Sião. | T25: 0.24 | U25: - | V25: - | W25: -
A26: DISVEL DISTRIBUIDORA DE FERMENTO VELOSO LTDA | B26: Paulo Marques | C26: 11 9 9744-5591 | D26: NÃO | E26: 116210 | F26: Distribuidor | G26: DISVEL DISTRIBUIDORA DE FERMENTO VELOSO LTDA | H26: 28440725000110 | I26: 80941001 | J26: Joao Veloso | K26: 2835210213 | N26: AVENIDA ARISTIDES CAMPOS, 72 | O26: CACHOEIRO DE ITAPEMIRIM | P26: ES | Q26: 29300700 | R26: disvel@gmail.com;fercal.ita@gmail.com; | S26: ESPÍRITO SANTO: Alegre, Alfredo Chaves, Anchieta, Apiacá, Atílio Vivácquam, Bom Jesus do Norte, Brejetuba, Cachoeiro de Itapemirim, Castelo, Conceição do Castelo, Divino São Lourenço, Dores do Rio Preto, Guaçuí, Guarapari, Ibatiba, Ibitirama, Iconha, Irupi, Itapemirim, Iúna, Jerônimo Monteiro, Marataízes, Mimoso do Sul, Muqui, Muniz Freire, Piúma, Presidente Kennedy, Rio Novo do Sul, São José do Calçado, Vargem Alta, Venda Nova do Imigrante | V26: 0.15 | W26: 0.15
A27: DUDAS BURGUER IND E COM DE PANIF LTDA | B27: Cláudio Cardoso | C27: 83 8 3822-0300 | D27: NÃO | E27: 106816 | F27: Distribuidor | G27: DUDAS BURGUER IND E COM DE PANIF LTDA | H27: 9215353000183 | I27: 63766507 | J27: Shellby | K27: 8532532025 | N27: AV. FRANCISCO AS, 2743 | O27: FORTALEZA | P27: CE | Q27: 60310000 | R27: comprasroyal@yahoo.com;comprasroyal2@yahoo.com; | S27: CE: FORTALEZA | T27: - | U27: - | V27: - | W27: -
A28: ELISANGELA CARDOSO SILVA | B28: Paulo Marques | C28: 11 9 9744-5591 | D28: NÃO | E28: 97407 | F28: Distribuidor | G28: ELISANGELA CARDOSO SILVA | H28: 4584107000185 | I28: 55790554 | J28: Cesar/Galego/Rosi | K28: 7332815550 | M28: 7332612999 | N28: AV. SANTOS DUMONT 726 | O28: EUNÁPOLIS | P28: BA | Q28: 45820011 | R28: disppan1@hotmail.com; | S28: BAHIA: Arraial D´Ajuda (Distrito de Porto Seguro), Belmonte, Eunápolis, Itabela, Itagimirim, Itapebi, Porto Seguro, Santa Cruz Cabrália, Barrolândia( Distrito Belmonte).(MINAS GERAIS) - Almenara, Itaobim, Jacinto, Jequitinhonha, Joaima, Pedra Azul, Rio do Pardo,Rubim, Salto da Divisa,Santa Maria do Salto,Santo Antônio do Jacinto. | T28: - | U28: - | V28: - | W28: -
A29: EMBRAPAN - EMPRESA BRASILEIRA DE PANIFICACAO - ME | B29: Paulo Marques | C29: 11 9 9744-5591 | D29: CONCESSÃO | E29: 110656 | F29: Distribuidor | G29: EMBRAPAN - EMPRESA BRASILEIRA DE PANIFICACAO - ME | H29: 3476733000195 | I29: 1860515000038 | J29: Rodrigo | K29: 3133571930 | N29: AV. SEVERINO BALLESTEROS, 1725 | O29: CONTAGEM | P29: MG | Q29: 32110005 | R29: financeiro@embrapan.com.br;rodrigogfortuna@hotmail.com | S29: MINAS GERAIS: Água Boa, Alvinópolis, Alvorada de Minas, Angelândia, Araçuaí, Aricanduva, Berilo, Braúnas, Cantagalo, Capelinha, Carbonita, Carmésia, Catas Altas, Chapada do Norte, Coluna, Congonhas do Norte, Coroaci, Couto de Magalhães de Minas, Divinolândia de Minas, Dom Joaquim, Dom Silvério, Dores de Guanhães, Felício dos Santos, Ferros, Francisco Badaró, Frei Lagonegro, Guanhães, Itabira, Itamarandiba, Itambé do Mato Dentro, Jenipapo de Minas, Joanésia, Malacacheta, Marilac, Materlândia, Minas Novas, Nacip Raydan, Passabém, Paulistas, Peçanha, Presidente Kubitschek, Rio Vermelho, Sabinópolis, Santa Bárbara, Santa Maria de Itabira, Santa Maria do Suaçuí, Santo Antônio do Itambé, São Geraldo da Piedade, São Gonçalo do Rio Preto, São João Evangelista, São José do Jacuri, São Pedro do Suaçuí, São Sebastião do Maranhão, São Sebastião do Rio Preto, Senador Modestino Gonçalves, Senhora do Porto, Serra Azul de Minas, Setubinha, Turmalina, Veredinha, Virgem da Lapa, Virginópolis, Virginópolis de Minas, Virgolândia. | T29: 0.17 | U29: 0.25 | V29: 0.15 | W29: 0.15
A30: FERMONTES COMERCIO LTDA. | B30: Paulo Marques | C30: 11 9 9744-5591 | D30: FRANQUIA | E30: 4316 | F30: Distribuidor | G30: FERMONTES COMERCIO LTDA. | H30: 2487988000190 | I30: 4337392530007 | J30: Ana Paula | K30: 3832149895 | N30: AV. RENE CALDEIRA 2000 | O30: MONTES CLAROS | P30: MG | Q30: 39401002 | R30: gerencia.compras@fermontes.com.br;financeiro@fermontes.com.br;fiscal@fermontes.com.br; | S30: MINAS GERAIS: Augusto de Lima, Bocaiúva, Brasília de Minas, Buenópolis, Buritizeiro, Capitão Enéas, Engenheiro Navarro, Espinosa, Francisco Sá, Grão Mogol, Jaíba, Janaúba, Jequitaí, Joaquim Felício, Lassance, Matias Cardoso, Mato Verde, Mirabela, Montalvânia ,Monte Azul,Montes Claros,Montezuma,Muzambinho,Pirapora,Porteirinha,Riacho dos Machados,Rio Pardo de Minas,Salinas,São João da Ponte,São João do Paraíso,São Romão,Taiobeiras,Vargem da Palma,Varzelândia. | T30: - | U30: - | V30: - | W30: -
A31: GELADOS E CONGELADOS DO VALE DISTR LTDA | B31: Franzen | C31: 51 9 9889-0857 | D31: NÃO | E31: 28000561 | F31: Distribuidor | G31: Frozen Foods | H31: 24.676.282/0001-00 | I31: NIRE 42205454784 | J31: Sr. Ronaldo Rosa | K31: (47) 3368-2442 | L31: (47) 99268-8237 | M31: _ | N31: R. Severino Cani, 150 | O31: Agronômica | P31: SC | Q31: 89188-000 | R31: agronomica@frozenfoodsalimentos.com.br | S31: SANTA CATARINA: Santa Terezinha, Doutor Pedrinho, Benedito novo,Vitor Meireles, Rio do Campo, Witmarsum, José Boiteux, Rodeio, Salete, Dona Emma, Ascurra, Taió, Presidente Getúlio, Ibitama, Apiúna, Lontras, Rio do Oeste, Laurentino, Mirim Doce, São Cristóvão do Sul, Pouso Redondo, Braço do Trombudo, Trombudo Central, Agronômica, Rio do Sul, Aurora e Presidente Nereu | T31: N/C | U31: N/C | V31: N/C | W31: N/C
A32: GJP COMERCIO DE ALIMENTOS EIRELLI EPP | B32: Cláudio Cardoso | C32: 83 8 3822-0300 | D32: NÃO | E32: 116215 | F32: Distribuidor | G32: GJP COMERCIO DE ALIMENTOS EIRELLI EPP | H32: 24292133000147 | I32: 66328152 | J32: JOSE EUCLIDES DE PAIVA | K32: 8132521690 | N32: RODOVIA BR 101 SUL, 305 | O32: RECIFE | P32: PE | Q32: 50790900 | R32: varejaodapadaria1@hotmail.com; | S32: PE: RECIFE | T32: - | U32: - | V32: - | W32: -
A33: GUIRADO REP E COMÉRCIO LTDA | B33: Wanessa Fabrina | C33: 11 9 8991-3766 | D33: SIM | E33: 1900296 | F33: Distribuidor | G33: Guirado | H33: 59 866 939/0001-86 | I33: 528 012 772 112 | J33: Sr. José Joir Zinoni Guirado e Sr. José Joir Zinoni Guirado Jr. | K33: (12) 3643-4040 | L33: (12) 99745-6858 | M33: (12) 3643-4141 | N33: R. Massami Ionemoto, 117 | O33: Pindamonhangaba | P33: SP | Q33: 12420-650 | R33: compras@jguirado.com.br | S33: SÃO PAULO: Aparecida, Arapeí, Areias, Bananal, Biritiba-Mirim, Caçapava, Cachoeira Paulista, Campos de Jordão, Canas, Cruzeiro, Cunha, Guararema, Guaratinguetá, Jacareí, Jambeiro, Lagoinha, Lavrinhas, Lorena, Monteiro Lobato, Natividade da Serra, Paraibuna, Pindamonhangaba, Piquete, Queluz, Redenção da Serra, Roseira, Salesópolis, Santa Branca, Santo Antônio do Pinhal, São Bento do Sapucaí, São José do Barreiro, São José dos Campos, São Luiz do Paraitinga, Silveiras, Taubaté, Tremembé. (No Estado de MINAS GERAIS) – Sapucaí-Mirim. | T33: 0.1353 | U33: - | V33: - | W33: -
A34: ITAVALE DISTRIB. LTDA - EPP | B34: Paulo Marques | C34: 11 9 9744-5591 | D34: FRANQUIA | E34: 905684 | F34: Distribuidor | G34: ITAVALE DISTRIB. LTDA - EPP | H34: 5452972000130 | I34: 3132163930017 | J34: Henrique/Katiana | K34: 3138257407 | M34: 99660748 | N34: R TACISIO SAMPAIO, 345 | O34: IPATINGA | P34: MG | Q34: 32164553 | R34: itavale.andrade@hotmail.com;industriadistrito@hotmail.com | S34: MINAS GERAIS: Abre Campo,Alto Caparão,Alto Jequitibá,Alvarenga,Bela Vista de Minas,Bom Jesus do Galho,Caiana ,Caparaó ,Caputira,Carangola,Caratinga,Chalé,Conceição de Ipanema,Coronel Fabriciano,Córrego Novo,Divino,Dom Cavati,Engenheiro Caldas,Entre Folhas ,Espera Feliz,Iapú,Imbé de Minas,Inhapim,Ipanema,Ipatinga,João Monlevade,Lajinha,Luisburgo,Manhuaçú,Manhumirim,Matipó,Mutum,Nova Era,Oratórios,Orizania ,Piedade de Caratinga,Piedade de Ponte Nova,Pingo-d'Água,Pocrane,Ponte Nova,Raul Soares,Reduto,Rio Casca,Santa Bárbara do Leste,Santa Cruz do Escalvado,Santa Margarida,Santa Rita de Minas,Santana do Manhuaçú,Santo Antônio do Grama,São João do Manhuaçu,São João do Oriente, São Pedro dos Ferros,Simonésia,Sobrália,Tarumirim,Timóteo,Ubaporanga,Urucânia,Vargem Alegre,Vermelho Novo. | T34: 0.1241 | U34: - | V34: 0.15 | W34: 0.15
A35: J. A. GASQUEZ - EPP | B35: Cláudio Cardoso | C35: 83 8 3822-0300 | D35: NÃO | E35: 102615 | F35: Distribuidor | G35: J. A. GASQUEZ - EPP | H35: 5981433000199 | I35: 152352058 | K35: 9137293554 | N35: RUA PRES COSTA E SILVA 201 | O35: PARAGOMINAS | P35: PA | Q35: 68625040 | R35: gaskys.alimentos@gmail.com; | S35: PA: PARAGOMINAS | T35: - | U35: - | V35: - | W35: -
A36: JENNY FRANK DOS SANTOS | B36: Cláudio Cardoso | C36: 83 8 3822-0300 | D36: NÃO | E36: 116116 | F36: Distribuidor | G36: JENNY FRANK DOS SANTOS | H36: 40188968000108 | I36: 205618774 | J36: JENNY FRANK DOS SANTOS | K36: 8432183653 | N36: RUA NOSSA SENHORA DE NAZARÉ, 1283 | O36: NATAL | P36: RN | Q36: 59031370 | R36: marciomctrigo@hotmail.com; | S36: RN: NATAL | T36: - | U36: - | V36: - | W36: -
A37: JG ESPACO DO CHEF LTDA | B37: Cláudio Cardoso | C37: 83 8 3822-0300 | D37: NÃO | E37: 115597 | F37: Distribuidor | G37: JG ESPACO DO CHEF LTDA | H37: 11977197000130 | I37: 202316211 | J37: JORGE BEZERRA GUEDES JUNIOR | K37: 1936579048 | N37: AV FRANCISCO TOMAZ VASCONCELOS, 360 | O37: PARNAMIRIM | P37: RN | Q37: 59140630 | R37: cleyton@jgdistribuidora.com;compras@jgdistribuidora.com;jefferson@jgdistribuidora.com;jorgejunior@jgdistribuidora.com; | S37: RN: PARNAMIRIM | T37: - | U37: - | V37: - | W37: -
A38: JULIA CORDEIRO FLORENCIO - COMERCIO | B38: Cláudio Cardoso | C38: 83 8 3822-0300 | D38: NÃO | E38: 117219 | F38: Distribuidor | G38: JULIA CORDEIRO FLORENCIO - COMERCIO | H38: 41894729000136 | I38: 96301716 | J38: JULIA CORDEIRO FLORENCIO | K38: 8194369276 | N38: AVENIDA ALLAN KARDEC, 162 | O38: CARUARU | P38: PE | Q38: 55014610 | R38: sotrigoatacado@gmail.com; | S38: PE: CARUARU | T38: - | U38: - | V38: - | W38: -
A39: KARNE KEIJO - LOGISTICA INTEGRADA LTDA | B39: Cláudio Cardoso | C39: 83 8 3822-0300 | D39: NÃO | E39: 114617 | F39: Distribuidor | G39: KARNE KEIJO - LOGISTICA INTEGRADA LTDA | H39: 24150377000780 | I39: 162059949 | K39: 8121218802 | N39: RUA BATISTA DA ROCHA, 30 | O39: JOÃO PESSOA | P39: PB | Q39: 58071705 | R39: carlosp@kk.com.br;elainea@kk.com.br;marcleias@kk.com.br; | S39: PB: JOÃO PESSOA | T39: - | U39: - | V39: - | W39: -
A40: KARNE KEIJO LOGISTICA INTEGRADA LTDA | B40: Cláudio Cardoso | C40: 83 8 3822-0300 | D40: NÃO | E40: 114539 | F40: Distribuidor | G40: KARNE KEIJO LOGISTICA INTEGRADA LTDA | H40: 24150377000195 | I40: 6682227 | J40: INACIO AMERICO DE MIRANDA JUNIOR | K40: 8132528899 | N40: RODOVIA BR - 101 SUL, 3700 | O40: RECIFE | P40: PE | Q40: 50780627 | R40: carlosp@kk.com.br;dandrade@kk.com.br;elainea@kk.com.br;marcleias@kk.com.br; | S40: PE: RECIFE | T40: - | U40: - | V40: - | W40: -
...
